Workbook

Sheet Maintenance PSURs
A1: MDR Certificate | B1: TD | C1: PSUR/PMSR ID | D1: Product Name | E1: Class | F1: Type | G1: Start Period | H1: End Period | I1: Frequency | J1: Due Date | K1: Status | L1: Writer | M1: Combined PSUR | N1: Notes | O1: Days Remaining | P1: Priority | Q1: Quarter | R1: Completion % | S1: Overdue?
A2: TBD | B2: TD002 | C2: PMS002R | D2: Leisegang Coloscopes | E2: I | F2: Medical Device | G2: 2021-01-01 | H2: 2025-12-31 | I2: 3 years | J2: 46113 | K2: In progress | L2: Terence | M2: None | N2: none | O2: =IF(K2="Completed","-",IF(ISNUMBER(J2),J2-TODAY(),"N/A")) -> -5 | P2: 🟠 URGENT | Q2: =IF(ISNUMBER(J2),"Q"&INT((MONTH(J2)-1)/3)+1&" "&YEAR(J2),"TBD") -> Q2 2026 | R2: =IF(K2="Completed",100,IF(K2="In progress",50,IF(K2="Assigned",25,IF(K2="Not Started",0,IF(K2="TBD",0,0))))) -> 50 | S2: =IF(AND(ISNUMBER(O2),O2<0,K2<>"Completed"),"⚠️ YES","No") -> ⚠️ YES
A3: TBD | B3: TD003 | C3: PMS003R | D3: Ally Uterine Positioning System | E3: I | F3: Medical Device | G3: 2023-01-01 | H3: 2025-12-31 | I3: 3 years | J3: 2026-01-15 | K3: In Review | L3: Terence | M3: None | N3: Determining the denominator | O3: =IF(K3="Completed","-",IF(ISNUMBER(J3),J3-TODAY(),"N/A")) -> N/A | P3: ⚪ TBD | Q3: =IF(ISNUMBER(J3),"Q"&INT((MONTH(J3)-1)/3)+1&" "&YEAR(J3),"TBD") -> TBD | R3: =IF(K3="Completed",100,IF(K3="In progress",50,IF(K3="Assigned",25,IF(K3="Not Started",0,IF(K3="TBD",0,0))))) -> 0 | S3: =IF(AND(ISNUMBER(O3),O3<0,K3<>"Completed"),"⚠️ YES","No") -> No
A4: TBD | B4: TBD | C4: PSUR007 | D4: LoneStar Retractor Kit | E4: IIa | F4: Medical Device | G4: 44927 | H4: 45657 | I4: 2 years | J4: 46073 | K4: In progress | L4: TBD | M4: None | O4: =IF(K4="Completed","-",IF(ISNUMBER(J4),J4-TODAY(),"N/A")) -> -45 | P4: 🔴 OVERDUE | Q4: =IF(ISNUMBER(J4),"Q"&INT((MONTH(J4)-1)/3)+1&" "&YEAR(J4),"TBD") -> Q1 2026 | R4: =IF(K4="Completed",100,IF(K4="In progress",50,IF(K4="Assigned",25,IF(K4="Not Started",0,IF(K4="TBD",0,0))))) -> 50 | S4: =IF(AND(ISNUMBER(O4),O4<0,K4<>"Completed"),"⚠️ YES","No") -> ⚠️ YES
A5: TBD | B5: TD007 | C5: PMS007R | D5: Retractors | E5: Is | F5: Medical Device | G5: TBD | H5: TBD | K5: Not Started | L5: TBD | M5: Combine with PSUR007 | O5: =IF(K5="Completed","-",IF(ISNUMBER(J5),J5-TODAY(),"N/A")) -> N/A | P5: ⚪ TBD | Q5: =IF(ISNUMBER(J5),"Q"&INT((MONTH(J5)-1)/3)+1&" "&YEAR(J5),"TBD") -> TBD | R5: =IF(K5="Completed",100,IF(K5="In progress",50,IF(K5="Assigned",25,IF(K5="Not Started",0,IF(K5="TBD",0,0))))) -> 0 | S5: =IF(AND(ISNUMBER(O5),O5<0,K5<>"Completed"),"⚠️ YES","No") -> No
A6: TBD | B6: TD008 | C6: PMS008R | D6: Endosee Hysteroscopy Product Family | E6: I | F6: Medical Device | G6: 2021-01-28 | H6: 2025-05-30 | I6: 3 years | J6: 2026-03-01 | K6: Completed | L6: Terence | M6: None | O6: =IF(K6="Completed","-",IF(ISNUMBER(J6),J6-TODAY(),"N/A")) -> - | P6: ✅ DONE | Q6: =IF(ISNUMBER(J6),"Q"&INT((MONTH(J6)-1)/3)+1&" "&YEAR(J6),"TBD") -> TBD | R6: =IF(K6="Completed",100,IF(K6="In progress",50,IF(K6="Assigned",25,IF(K6="Not Started",0,IF(K6="TBD",0,0))))) -> 100 | S6: =IF(AND(ISNUMBER(O6),O6<0,K6<>"Completed"),"⚠️ YES","No") -> No
A7: TBD | B7: TD009 | C7: PMS009R | D7: Comfit Trake - Nofit, NEO-prep | E7: I | F7: Medical Device | G7: 43952 | H7: 46022 | I7: 3 years | K7: In Review | L7: Terence | O7: =IF(K7="Completed","-",IF(ISNUMBER(J7),J7-TODAY(),"N/A")) -> N/A | P7: ⚪ TBD | Q7: =IF(ISNUMBER(J7),"Q"&INT((MONTH(J7)-1)/3)+1&" "&YEAR(J7),"TBD") -> TBD | R7: =IF(K7="Completed",100,IF(K7="In progress",50,IF(K7="Assigned",25,IF(K7="Not Started",0,IF(K7="TBD",0,0))))) -> 0 | S7: =IF(AND(ISNUMBER(O7),O7<0,K7<>"Completed"),"⚠️ YES","No") -> No
A8: TBD | B8: TD062 | C8: PMS062R | D8: Endometrial_Suction_Curette | E8: I | F8: TBD | I8: TBD | J8: Immediate | K8: Not Started | L8: TBD | M8: None | N8: No available documents released in MC | O8: =IF(K8="Completed","-",IF(ISNUMBER(J8),J8-TODAY(),"N/A")) -> N/A | P8: ⚪ TBD | Q8: =IF(ISNUMBER(J8),"Q"&INT((MONTH(J8)-1)/3)+1&" "&YEAR(J8),"TBD") -> TBD | R8: =IF(K8="Completed",100,IF(K8="In progress",50,IF(K8="Assigned",25,IF(K8="Not Started",0,IF(K8="TBD",0,0))))) -> 0 | S8: =IF(AND(ISNUMBER(O8),O8<0,K8<>"Completed"),"⚠️ YES","No") -> No
A9: TBD | B9: TD123 | C9: PMS123R | D9: K-Systems Flex Short-term Incubator Module | E9: I | F9: Fertility | G9: 44561 | H9: 46751 | I9: 3 years | K9: Not Started | L9: TBD | M9: None | N9: Terence will be conforming | O9: =IF(K9="Completed","-",IF(ISNUMBER(J9),J9-TODAY(),"N/A")) -> N/A | P9: ⚪ TBD | Q9: =IF(ISNUMBER(J9),"Q"&INT((MONTH(J9)-1)/3)+1&" "&YEAR(J9),"TBD") -> TBD | R9: =IF(K9="Completed",100,IF(K9="In progress",50,IF(K9="Assigned",25,IF(K9="Not Started",0,IF(K9="TBD",0,0))))) -> 0 | S9: =IF(AND(ISNUMBER(O9),O9<0,K9<>"Completed"),"⚠️ YES","No") -> No
A10: TBD | B10: TD124 | C10: PMS124R | D10: Embryo Biopsy Kit | E10: I | F10: Medical Device | G10: 44561 | H10: 46751 | I10: 3 years | K10: Not Started | L10: TBD | M10: None | N10: Terence will be conforming | O10: =IF(K10="Completed","-",IF(ISNUMBER(J10),J10-TODAY(),"N/A")) -> N/A | P10: ⚪ TBD | Q10: =IF(ISNUMBER(J10),"Q"&INT((MONTH(J10)-1)/3)+1&" "&YEAR(J10),"TBD") -> TBD | R10: =IF(K10="Completed",100,IF(K10="In progress",50,IF(K10="Assigned",25,IF(K10="Not Started",0,IF(K10="TBD",0,0))))) -> 0 | S10: =IF(AND(ISNUMBER(O10),O10<0,K10<>"Completed"),"⚠️ YES","No") -> No
A11: TBD | B11: TD125 | C11: PMS125R | D11: Endometrial Biopsy Kit | E11: I | F11: Medical Device | G11: 44926 | H11: 47117 | I11: 3 years | K11: Not Started | L11: TBD | M11: None | N11: Terence will be conforming | O11: =IF(K11="Completed","-",IF(ISNUMBER(J11),J11-TODAY(),"N/A")) -> N/A | P11: ⚪ TBD | Q11: =IF(ISNUMBER(J11),"Q"&INT((MONTH(J11)-1)/3)+1&" "&YEAR(J11),"TBD") -> TBD | R11: =IF(K11="Completed",100,IF(K11="In progress",50,IF(K11="Assigned",25,IF(K11="Not Started",0,IF(K11="TBD",0,0))))) -> 0 | S11: =IF(AND(ISNUMBER(O11),O11<0,K11<>"Completed"),"⚠️ YES","No") -> No
A12: TBD | B12: TD017 | C12: PMSR017 | D12: EZ-Grip & Comfort Rest | E12: I | F12: Fertility | G12: 2021-01-01 | H12: 2026-01-14 | I12: 3 years | J12: 2026-01-23 | K12: In Review | L12: Terence | M12: None | N12: Need to check with Terence | O12: =IF(K12="Completed","-",IF(ISNUMBER(J12),J12-TODAY(),"N/A")) -> N/A | P12: ⚪ TBD | Q12: =IF(ISNUMBER(J12),"Q"&INT((MONTH(J12)-1)/3)+1&" "&YEAR(J12),"TBD") -> TBD | R12: =IF(K12="Completed",100,IF(K12="In progress",50,IF(K12="Assigned",25,IF(K12="Not Started",0,IF(K12="TBD",0,0))))) -> 0 | S12: =IF(AND(ISNUMBER(O12),O12<0,K12<>"Completed"),"⚠️ YES","No") -> No
A13: TBD | B13: TD018 | C13: PSUR018 | D13: LEEP ELECTRODES | E13: IIb | F13: Medical Device | G13: 45809 | H13: 46173 | I13: 1 year | J13: 46290 | K13: Not Started | L13: TBD | M13: None | O13: =IF(K13="Completed","-",IF(ISNUMBER(J13),J13-TODAY(),"N/A")) -> 172 | P13: 🟢 ON TRACK | Q13: =IF(ISNUMBER(J13),"Q"&INT((MONTH(J13)-1)/3)+1&" "&YEAR(J13),"TBD") -> Q3 2026 | R13: =IF(K13="Completed",100,IF(K13="In progress",50,IF(K13="Assigned",25,IF(K13="Not Started",0,IF(K13="TBD",0,0))))) -> 0 | S13: =IF(AND(ISNUMBER(O13),O13<0,K13<>"Completed"),"⚠️ YES","No") -> No
A14: TBD | B14: TD039 | C14: PSUR039 | D14: Acidified Tyrodes Solution (1060) | E14: III | F14: Media | G14: 45474 | H14: 45838 | I14: 1 year | J14: 46112 | K14: In progress | L14: Harish | M14: None | N14: none | O14: =IF(K14="Completed","-",IF(ISNUMBER(J14),J14-TODAY(),"N/A")) -> -6 | P14: 🟠 URGENT | Q14: =IF(ISNUMBER(J14),"Q"&INT((MONTH(J14)-1)/3)+1&" "&YEAR(J14),"TBD") -> Q1 2026 | R14: =IF(K14="Completed",100,IF(K14="In progress",50,IF(K14="Assigned",25,IF(K14="Not Started",0,IF(K14="TBD",0,0))))) -> 50 | S14: =IF(AND(ISNUMBER(O14),O14<0,K14<>"Completed"),"⚠️ YES","No") -> ⚠️ YES
A15: MDR 768070 | B15: TD041 | C15: PSUR041 | D15: Liquid Paraffin - CHANGE CURRENT REV C TO B AND B TO A | E15: IIa | F15: Media | G15: 45292 | H15: 46022 | I15: 2 years | J15: 46157 | K15: Not Started | L15: Jeff | M15: Combine in PSUR041 | N15: PSUR041, PSUR205, PSUR301, PSUR302 and PSUR303 are combined in PSUR041 | O15: =IF(K15="Completed","-",IF(ISNUMBER(J15),J15-TODAY(),"N/A")) -> 39 | P15: 🟡 SOON | Q15: =IF(ISNUMBER(J15),"Q"&INT((MONTH(J15)-1)/3)+1&" "&YEAR(J15),"TBD") -> Q2 2026 | R15: =IF(K15="Completed",100,IF(K15="In progress",50,IF(K15="Assigned",25,IF(K15="Not Started",0,IF(K15="TBD",0,0))))) -> 0 | S15: =IF(AND(ISNUMBER(O15),O15<0,K15<>"Completed"),"⚠️ YES","No") -> No
A16: MDR 768070 | B16: TD044 | C16: PSUR044 | D16: VitriFit™ | E16: IIa | F16: Media | G16: 45292 | H16: 46022 | I16: 2 years | J16: 46150 | K16: Not Started | L16: Jeff | M16: None | N16: none | O16: =IF(K16="Completed","-",IF(ISNUMBER(J16),J16-TODAY(),"N/A")) -> 32 | P16: 🟡 SOON | Q16: =IF(ISNUMBER(J16),"Q"&INT((MONTH(J16)-1)/3)+1&" "&YEAR(J16),"TBD") -> Q2 2026 | R16: =IF(K16="Completed",100,IF(K16="In progress",50,IF(K16="Assigned",25,IF(K16="Not Started",0,IF(K16="TBD",0,0))))) -> 0 | S16: =IF(AND(ISNUMBER(O16),O16<0,K16<>"Completed"),"⚠️ YES","No") -> No
A17: TBD | B17: TD049 | C17: PSUR049 | D17: Saturn 5 Laser System | E17: IIb | F17: Fertility | G17: 45292 | H17: 46022 | I17: 1 year | J17: 46094 | K17: Not Started | L17: Venkata | M17: None | N17: CER deadline 02 March 2026 | O17: =IF(K17="Completed","-",IF(ISNUMBER(J17),J17-TODAY(),"N/A")) -> -24 | P17: 🔴 OVERDUE | Q17: =IF(ISNUMBER(J17),"Q"&INT((MONTH(J17)-1)/3)+1&" "&YEAR(J17),"TBD") -> Q1 2026 | R17: =IF(K17="Completed",100,IF(K17="In progress",50,IF(K17="Assigned",25,IF(K17="Not Started",0,IF(K17="TBD",0,0))))) -> 0 | S17: =IF(AND(ISNUMBER(O17),O17<0,K17<>"Completed"),"⚠️ YES","No") -> ⚠️ YES
A18: TBD | B18: TD050 | C18: PSUR050 | D18: RI Witness EHP | E18: IIa | F18: Fertility | G18: 44621 | H18: 45808 | I18: 2 years | J18: 46080 | K18: In Review | L18: Jeff | M18: None | N18: In draft, need to release 3-6-26 Awaiting Sales/complaint data, updating to new template | O18: =IF(K18="Completed","-",IF(ISNUMBER(J18),J18-TODAY(),"N/A")) -> -38 | P18: 🔴 OVERDUE | Q18: =IF(ISNUMBER(J18),"Q"&INT((MONTH(J18)-1)/3)+1&" "&YEAR(J18),"TBD") -> Q1 2026 | R18: =IF(K18="Completed",100,IF(K18="In progress",50,IF(K18="Assigned",25,IF(K18="Not Started",0,IF(K18="TBD",0,0))))) -> 0 | S18: =IF(AND(ISNUMBER(O18),O18<0,K18<>"Completed"),"⚠️ YES","No") -> ⚠️ YES
A19: TBD | B19: TD070 | C19: PSUR070 | D19: Medical Heatpacks | E19: IIa | F19: Medical Device | G19: 45108 | H19: 45838 | I19: 2 years | J19: 46080 | K19: In progress | L19: Venkata | M19: None | N19: none | O19: =IF(K19="Completed","-",IF(ISNUMBER(J19),J19-TODAY(),"N/A")) -> -38 | P19: 🔴 OVERDUE | Q19: =IF(ISNUMBER(J19),"Q"&INT((MONTH(J19)-1)/3)+1&" "&YEAR(J19),"TBD") -> Q1 2026 | R19: =IF(K19="Completed",100,IF(K19="In progress",50,IF(K19="Assigned",25,IF(K19="Not Started",0,IF(K19="TBD",0,0))))) -> 50 | S19: =IF(AND(ISNUMBER(O19),O19<0,K19<>"Completed"),"⚠️ YES","No") -> ⚠️ YES
A20: MDR 768179 | B20: TD047 | C20: PSUR047 | D20: SynVitro® Hyadase | E20: III | F20: Media | G20: 45839 | H20: 46203 | I20: 1 year | J20: 46233 | K20: Not Started | L20: TBD | M20: None | N20: none | O20: =IF(K20="Completed","-",IF(ISNUMBER(J20),J20-TODAY(),"N/A")) -> 115 | P20: 🟢 ON TRACK | Q20: =IF(ISNUMBER(J20),"Q"&INT((MONTH(J20)-1)/3)+1&" "&YEAR(J20),"TBD") -> Q3 2026 | R20: =IF(K20="Completed",100,IF(K20="In progress",50,IF(K20="Assigned",25,IF(K20="Not Started",0,IF(K20="TBD",0,0))))) -> 0 | S20: =IF(AND(ISNUMBER(O20),O20<0,K20<>"Completed"),"⚠️ YES","No") -> No
A21: TBD | B21: TD048 | C21: PSUR048 | D21: Integra 3 Micromanipulator | E21: IIa | F21: Fertility | G21: 45474 | H21: 46203 | I21: 2 years | J21: 46233 | K21: Not Started | L21: TBD | M21: None | O21: =IF(K21="Completed","-",IF(ISNUMBER(J21),J21-TODAY(),"N/A")) -> 115 | P21: 🟢 ON TRACK | Q21: =IF(ISNUMBER(J21),"Q"&INT((MONTH(J21)-1)/3)+1&" "&YEAR(J21),"TBD") -> Q3 2026 | R21: =IF(K21="Completed",100,IF(K21="In progress",50,IF(K21="Assigned",25,IF(K21="Not Started",0,IF(K21="TBD",0,0))))) -> 0 | S21: =IF(AND(ISNUMBER(O21),O21<0,K21<>"Completed"),"⚠️ YES","No") -> No
A22: TBD | B22: TD071 | C22: PSUR071 | D22: Mobius Elastic Retractors | E22: IIa | F22: TBD | G22: 45047 | H22: 45777 | I22: 2 years | J22: 46094 | K22: In progress | L22: Jeff | M22: None | N22: Sales data request issued 3-24-26 | O22: =IF(K22="Completed","-",IF(ISNUMBER(J22),J22-TODAY(),"N/A")) -> -24 | P22: 🔴 OVERDUE | Q22: =IF(ISNUMBER(J22),"Q"&INT((MONTH(J22)-1)/3)+1&" "&YEAR(J22),"TBD") -> Q1 2026 | R22: =IF(K22="Completed",100,IF(K22="In progress",50,IF(K22="Assigned",25,IF(K22="Not Started",0,IF(K22="TBD",0,0))))) -> 50 | S22: =IF(AND(ISNUMBER(O22),O22<0,K22<>"Completed"),"⚠️ YES","No") -> ⚠️ YES
A23: TBD | B23: TD051 | C23: PSUR051 | D23: EZ-Range Pipettes | E23: IIb | F23: Fertility | G23: 45352 | H23: 46081 | I23: 1 year | J23: 46164 | K23: Not Started | L23: Venkata | M23: None | N23: none | O23: =IF(K23="Completed","-",IF(ISNUMBER(J23),J23-TODAY(),"N/A")) -> 46 | P23: 🟡 SOON | Q23: =IF(ISNUMBER(J23),"Q"&INT((MONTH(J23)-1)/3)+1&" "&YEAR(J23),"TBD") -> Q2 2026 | R23: =IF(K23="Completed",100,IF(K23="In progress",50,IF(K23="Assigned",25,IF(K23="Not Started",0,IF(K23="TBD",0,0))))) -> 0 | S23: =IF(AND(ISNUMBER(O23),O23<0,K23<>"Completed"),"⚠️ YES","No") -> No
A24: TBD | B24: TD077 | C24: PSUR077 | D24: Wallace Oocyte Recovery/Collection Sets | E24: IIa | F24: Medical Device | G24: 44652 | H24: 45747 | I24: 2 years | J24: 46073 | K24: In progress | L24: Venkata | M24: None | N24: Routing in MC | O24: =IF(K24="Completed","-",IF(ISNUMBER(J24),J24-TODAY(),"N/A")) -> -45 | P24: 🔴 OVERDUE | Q24: =IF(ISNUMBER(J24),"Q"&INT((MONTH(J24)-1)/3)+1&" "&YEAR(J24),"TBD") -> Q1 2026 | R24: =IF(K24="Completed",100,IF(K24="In progress",50,IF(K24="Assigned",25,IF(K24="Not Started",0,IF(K24="TBD",0,0))))) -> 50 | S24: =IF(AND(ISNUMBER(O24),O24<0,K24<>"Completed"),"⚠️ YES","No") -> ⚠️ YES
A25: TBD | B25: TD058 | C25: PSUR058 | D25: Apple-Hunt Trocars | E25: IIa | F25: TBD | G25: 45383 | H25: 46112 | I25: 2 years | J25: 46186 | K25: Not Started | L25: Jeff | M25: None | N25: none | O25: =IF(K25="Completed","-",IF(ISNUMBER(J25),J25-TODAY(),"N/A")) -> 68 | P25: 🟢 ON TRACK | Q25: =IF(ISNUMBER(J25),"Q"&INT((MONTH(J25)-1)/3)+1&" "&YEAR(J25),"TBD") -> Q2 2026 | R25: =IF(K25="Completed",100,IF(K25="In progress",50,IF(K25="Assigned",25,IF(K25="Not Started",0,IF(K25="TBD",0,0))))) -> 0 | S25: =IF(AND(ISNUMBER(O25),O25<0,K25<>"Completed"),"⚠️ YES","No") -> No
A26: TBD | B26: TD060 | C26: PSUR060 | D26: Carter-Thomason Port Closure Products | E26: IIa | F26: TBD | G26: 45505 | H26: 46234 | I26: 2 years | J26: 46262 | K26: Not Started | L26: TBD | M26: None | N26: none | O26: =IF(K26="Completed","-",IF(ISNUMBER(J26),J26-TODAY(),"N/A")) -> 144 | P26: 🟢 ON TRACK | Q26: =IF(ISNUMBER(J26),"Q"&INT((MONTH(J26)-1)/3)+1&" "&YEAR(J26),"TBD") -> Q3 2026 | R26: =IF(K26="Completed",100,IF(K26="In progress",50,IF(K26="Assigned",25,IF(K26="Not Started",0,IF(K26="TBD",0,0))))) -> 0 | S26: =IF(AND(ISNUMBER(O26),O26<0,K26<>"Completed"),"⚠️ YES","No") -> No
A27: TBD | B27: TD081 | C27: PSUR081 | D27: Fischer cone Biopsy Electrodes | E27: IIb | F27: Medical Device | G27: 45474 | H27: 45838 | I27: 1 year | J27: 46087 | K27: In progress | L27: Terence | M27: None | N27: none | O27: =IF(K27="Completed","-",IF(ISNUMBER(J27),J27-TODAY(),"N/A")) -> -31 | P27: 🔴 OVERDUE | Q27: =IF(ISNUMBER(J27),"Q"&INT((MONTH(J27)-1)/3)+1&" "&YEAR(J27),"TBD") -> Q1 2026 | R27: =IF(K27="Completed",100,IF(K27="In progress",50,IF(K27="Assigned",25,IF(K27="Not Started",0,IF(K27="TBD",0,0))))) -> 50 | S27: =IF(AND(ISNUMBER(O27),O27<0,K27<>"Completed"),"⚠️ YES","No") -> ⚠️ YES
A28: TBD | B28: TD087 | C28: PSUR087 | D28: LifeGlobal Dishes GPS® Dishware | E28: IIa | F28: Media | G28: 45444 | H28: 46173 | I28: 2 years | J28: 46199 | K28: Not Started | L28: Jeff | M28: None | N28: none | O28: =IF(K28="Completed","-",IF(ISNUMBER(J28),J28-TODAY(),"N/A")) -> 81 | P28: 🟢 ON TRACK | Q28: =IF(ISNUMBER(J28),"Q"&INT((MONTH(J28)-1)/3)+1&" "&YEAR(J28),"TBD") -> Q2 2026 | R28: =IF(K28="Completed",100,IF(K28="In progress",50,IF(K28="Assigned",25,IF(K28="Not Started",0,IF(K28="TBD",0,0))))) -> 0 | S28: =IF(AND(ISNUMBER(O28),O28<0,K28<>"Completed"),"⚠️ YES","No") -> No
A29: TBD | B29: TD069 | C29: PSUR069 | D29: Lone Star Elastic Stays | E29: IIa | F29: Fertility | G29: 45383 | H29: 46112 | I29: 2 years | J29: 46179 | K29: Not Started | L29: Venkata | M29: None | N29: none | O29: =IF(K29="Completed","-",IF(ISNUMBER(J29),J29-TODAY(),"N/A")) -> 61 | P29: 🟢 ON TRACK | Q29: =IF(ISNUMBER(J29),"Q"&INT((MONTH(J29)-1)/3)+1&" "&YEAR(J29),"TBD") -> Q2 2026 | R29: =IF(K29="Completed",100,IF(K29="In progress",50,IF(K29="Assigned",25,IF(K29="Not Started",0,IF(K29="TBD",0,0))))) -> 0 | S29: =IF(AND(ISNUMBER(O29),O29<0,K29<>"Completed"),"⚠️ YES","No") -> No
A30: TBD | B30: TD082 | C30: PSUR082 | D30: Pessary Product Family | E30: IIb | F30: Medical Device | G30: 44652 | H30: 45991 | I30: 1 year | J30: 46076 | K30: Completed | L30: Venkata | M30: None | N30: none | O30: =IF(K30="Completed","-",IF(ISNUMBER(J30),J30-TODAY(),"N/A")) -> - | P30: ✅ DONE | Q30: =IF(ISNUMBER(J30),"Q"&INT((MONTH(J30)-1)/3)+1&" "&YEAR(J30),"TBD") -> Q1 2026 | R30: =IF(K30="Completed",100,IF(K30="In progress",50,IF(K30="Assigned",25,IF(K30="Not Started",0,IF(K30="TBD",0,0))))) -> 100 | S30: =IF(AND(ISNUMBER(O30),O30<0,K30<>"Completed"),"⚠️ YES","No") -> No
A31: TBD | C31: PSUR068 | D31: Wallace Aspiration Pump | E31: I | F31: TBD | I31: TBD | J31: 04/30/2026 - Immediate | K31: Not Started | L31: Jeff | M31: None | N31: No available documents released in MC | O31: =IF(K31="Completed","-",IF(ISNUMBER(J31),J31-TODAY(),"N/A")) -> N/A | P31: ⚪ TBD | Q31: =IF(ISNUMBER(J31),"Q"&INT((MONTH(J31)-1)/3)+1&" "&YEAR(J31),"TBD") -> TBD | R31: =IF(K31="Completed",100,IF(K31="In progress",50,IF(K31="Assigned",25,IF(K31="Not Started",0,IF(K31="TBD",0,0))))) -> 0 | S31: =IF(AND(ISNUMBER(O31),O31<0,K31<>"Completed"),"⚠️ YES","No") -> No
A32: TBD | B32: TD073 | C32: PSUR073 | D32: IVF PASTEUR PIPETTES | E32: IIa | F32: Medical Device | G32: 45474 | H32: 46203 | I32: 2 years | J32: 46241 | K32: Not Started | L32: TBD | M32: None | N32: none | O32: =IF(K32="Completed","-",IF(ISNUMBER(J32),J32-TODAY(),"N/A")) -> 123 | P32: 🟢 ON TRACK | Q32: =IF(ISNUMBER(J32),"Q"&INT((MONTH(J32)-1)/3)+1&" "&YEAR(J32),"TBD") -> Q3 2026 | R32: =IF(K32="Completed",100,IF(K32="In progress",50,IF(K32="Assigned",25,IF(K32="Not Started",0,IF(K32="TBD",0,0))))) -> 0 | S32: =IF(AND(ISNUMBER(O32),O32<0,K32<>"Completed"),"⚠️ YES","No") -> No
A33: TBD | B33: TD083 | C33: PSUR083 | D33: LifeDop Dopplers and Probes | E33: IIa | F33: Medical Device | G33: 45139 | H33: 45869 | I33: 2 years | J33: 46108 | K33: In progress | L33: Jeff | M33: None | N33: none | O33: =IF(K33="Completed","-",IF(ISNUMBER(J33),J33-TODAY(),"N/A")) -> -10 | P33: 🔴 OVERDUE | Q33: =IF(ISNUMBER(J33),"Q"&INT((MONTH(J33)-1)/3)+1&" "&YEAR(J33),"TBD") -> Q1 2026 | R33: =IF(K33="Completed",100,IF(K33="In progress",50,IF(K33="Assigned",25,IF(K33="Not Started",0,IF(K33="TBD",0,0))))) -> 50 | S33: =IF(AND(ISNUMBER(O33),O33<0,K33<>"Completed"),"⚠️ YES","No") -> ⚠️ YES
A34: TBD | B34: TD007 | C34: PMS007R | D34: Adult-Neonatal_Care | E34: I | F34: Medical Device | I34: TBD | J34: 2026-01-03 | K34: Not Started | L34: Jeff | M34: None | N34: none | O34: =IF(K34="Completed","-",IF(ISNUMBER(J34),J34-TODAY(),"N/A")) -> N/A | P34: ⚪ TBD | Q34: =IF(ISNUMBER(J34),"Q"&INT((MONTH(J34)-1)/3)+1&" "&YEAR(J34),"TBD") -> TBD | R34: =IF(K34="Completed",100,IF(K34="In progress",50,IF(K34="Assigned",25,IF(K34="Not Started",0,IF(K34="TBD",0,0))))) -> 0 | S34: =IF(AND(ISNUMBER(O34),O34<0,K34<>"Completed"),"⚠️ YES","No") -> No
A35: TBD | B35: TD059 | C35: PSUR059 | D35: Assisted Reproduction Catheters | E35: I | F35: Medical Device | I35: 3 years | J35: 4/30/2026 - Immediate | K35: Not Started | L35: Jeff | M35: None | N35: No available documents released in MC | O35: =IF(K35="Completed","-",IF(ISNUMBER(J35),J35-TODAY(),"N/A")) -> N/A | P35: ⚪ TBD | Q35: =IF(ISNUMBER(J35),"Q"&INT((MONTH(J35)-1)/3)+1&" "&YEAR(J35),"TBD") -> TBD | R35: =IF(K35="Completed",100,IF(K35="In progress",50,IF(K35="Assigned",25,IF(K35="Not Started",0,IF(K35="TBD",0,0))))) -> 0 | S35: =IF(AND(ISNUMBER(O35),O35<0,K35<>"Completed"),"⚠️ YES","No") -> No
A36: TBD | B36: TD103 | C36: PSUR103 | D36: Micropipettes, Biopsy, ICISI_x000D__x000D__x000D_ Assisted Hatching (Mechanical and Chemical)_x000D__x000D__x000D_ Holding | E36: IIb | F36: Medical Device | G36: 44652 | H36: 46022 | I36: 1 year | J36: 2/20/2026 - Immediate | K36: Completed | L36: Terence | M36: None | N36: CER deadline 19 January 2026 | O36: =IF(K36="Completed","-",IF(ISNUMBER(J36),J36-TODAY(),"N/A")) -> - | P36: ✅ DONE | Q36: =IF(ISNUMBER(J36),"Q"&INT((MONTH(J36)-1)/3)+1&" "&YEAR(J36),"TBD") -> TBD | R36: =IF(K36="Completed",100,IF(K36="In progress",50,IF(K36="Assigned",25,IF(K36="Not Started",0,IF(K36="TBD",0,0))))) -> 100 | S36: =IF(AND(ISNUMBER(O36),O36<0,K36<>"Completed"),"⚠️ YES","No") -> No
A37: TBD | B37: TD129 | C37: PSUR129 | D37: Cook Doppler blood flow monitor products | E37: IIb | F37: Medical Device | G37: 45536 | H37: 45900 | I37: 1 year | J37: 46080 | K37: In Review | L37: Terence | M37: None | O37: =IF(K37="Completed","-",IF(ISNUMBER(J37),J37-TODAY(),"N/A")) -> -38 | P37: 🔴 OVERDUE | Q37: =IF(ISNUMBER(J37),"Q"&INT((MONTH(J37)-1)/3)+1&" "&YEAR(J37),"TBD") -> Q1 2026 | R37: =IF(K37="Completed",100,IF(K37="In progress",50,IF(K37="Assigned",25,IF(K37="Not Started",0,IF(K37="TBD",0,0))))) -> 0 | S37: =IF(AND(ISNUMBER(O37),O37<0,K37<>"Completed"),"⚠️ YES","No") -> ⚠️ YES
A38: TBD | B38: TD104 | C38: PSUR104 | D38: HBA Biocoat | E38: I | F38: TBD | I38: TBD | J38: 46101 | K38: In progress | L38: Terence | M38: None | N38: No available documents released in MC | O38: =IF(K38="Completed","-",IF(ISNUMBER(J38),J38-TODAY(),"N/A")) -> -17 | P38: 🔴 OVERDUE | Q38: =IF(ISNUMBER(J38),"Q"&INT((MONTH(J38)-1)/3)+1&" "&YEAR(J38),"TBD") -> Q1 2026 | R38: =IF(K38="Completed",100,IF(K38="In progress",50,IF(K38="Assigned",25,IF(K38="Not Started",0,IF(K38="TBD",0,0))))) -> 50 | S38: =IF(AND(ISNUMBER(O38),O38<0,K38<>"Completed"),"⚠️ YES","No") -> ⚠️ YES
A39: TBD | B39: TD105 | C39: PSUR105 | D39: Stripper Tips | E39: IIB | F39: Medical Device | G39: 45839 | H39: 46203 | I39: 1 year | J39: 46234 | K39: Not Started | L39: TBD | M39: None | O39: =IF(K39="Completed","-",IF(ISNUMBER(J39),J39-TODAY(),"N/A")) -> 116 | P39: 🟢 ON TRACK | Q39: =IF(ISNUMBER(J39),"Q"&INT((MONTH(J39)-1)/3)+1&" "&YEAR(J39),"TBD") -> Q3 2026 | R39: =IF(K39="Completed",100,IF(K39="In progress",50,IF(K39="Assigned",25,IF(K39="Not Started",0,IF(K39="TBD",0,0))))) -> 0 | S39: =IF(AND(ISNUMBER(O39),O39<0,K39<>"Completed"),"⚠️ YES","No") -> No
A40: TBD | B40: TD118 | C40: PSUR118 | D40: OBP AnoSpec Lighted Anoscopes | E40: I | F40: Medical Device | I40: 3 years | J40: 03/27/2026 - Immediate | K40: Not Started | L40: Terence | M40: None | N40: No documents available in MC | O40: =IF(K40="Completed","-",IF(ISNUMBER(J40),J40-TODAY(),"N/A")) -> N/A | P40: ⚪ TBD | Q40: =IF(ISNUMBER(J40),"Q"&INT((MONTH(J40)-1)/3)+1&" "&YEAR(J40),"TBD") -> TBD | R40: =IF(K40="Completed",100,IF(K40="In progress",50,IF(K40="Assigned",25,IF(K40="Not Started",0,IF(K40="TBD",0,0))))) -> 0 | S40: =IF(AND(ISNUMBER(O40),O40<0,K40<>"Completed"),"⚠️ YES","No") -> No
...

Sheet BSI Dashboard
A1: 📊 BSI PSUR DASHBOARD — Q1 & Q2 2026
A3: KEY PERFORMANCE INDICATORS
A4: Total BSI Certificates | C4: Completed | E4: In Progress | G4: In Review | I4: Not Started | K4: Overdue | M4: Overall Progress
A5: {=SUMPRODUCT(('BSI PSURs'!A2:A45<>"")*('BSI PSURs'!A2:A45<>"TBD")*(1/COUNTIF('BSI PSURs'!A2:A45,'BSI PSURs'!A2:A45&"")))} -> 23 | C5: {=SUMPRODUCT(('BSI PSURs'!A2:A45<>"")*('BSI PSURs'!A2:A45<>"TBD")*('BSI PSURs'!K2:K45="Completed")*(1/COUNTIF('BSI PSURs'!A2:A45,'BSI PSURs'!A2:A45&"")))} -> 7 | E5: {=SUMPRODUCT(('BSI PSURs'!A2:A45<>"")*('BSI PSURs'!A2:A45<>"TBD")*('BSI PSURs'!K2:K45="In progress")*(1/COUNTIF('BSI PSURs'!A2:A45,'BSI PSURs'!A2:A45&"")))} -> 1 | G5: {=SUMPRODUCT(('BSI PSURs'!A2:A45<>"")*('BSI PSURs'!A2:A45<>"TBD")*('BSI PSURs'!K2:K45="In Review")*(1/COUNTIF('BSI PSURs'!A2:A45,'BSI PSURs'!A2:A45&"")))} -> 3 | I5: {=SUMPRODUCT(('BSI PSURs'!A2:A45<>"")*('BSI PSURs'!A2:A45<>"TBD")*('BSI PSURs'!K2:K45="Not Started")*(1/COUNTIF('BSI PSURs'!A2:A45,'BSI PSURs'!A2:A45&"")))} -> 11 | K5: {=SUMPRODUCT(('BSI PSURs'!A2:A45<>"")*('BSI PSURs'!A2:A45<>"TBD")*('BSI PSURs'!S2:S45="⚠️ YES")*(1/COUNTIF('BSI PSURs'!A2:A45,'BSI PSURs'!A2:A45&"")))} -> 0 | M5: =IFERROR(C5/A5,0) -> 0.30434783
A7: 📊 STATUS BREAKDOWN | E7: 👤 WRITER WORKLOAD | I7: 📅 QUARTERLY VIEW
A8: Status | B8: Count | C8: % of Total | E8: Writer | F8: Assigned | G8: Completed | I8: Quarter | J8: Total | K8: Completed | L8: % Done
A9: Completed | B9: =C5 -> 7 | C9: =IFERROR(B9/$A$5,0) -> 0.30434783 | E9: Harish | F9: 9 | G9: 5 | I9: Q1 2026 | J9: 9 | K9: 8 | L9: =K9/J9 -> 0.88888889
A10: In progress | B10: =E5 -> 1 | C10: =IFERROR(B10/$A$5,0) -> 0.043478261 | E10: Jeff | F10: 3 | G10: 2 | I10: Q2 2026 | J10: 11 | K10: 0 | L10: =K10/J10 -> 0
A11: In Review | B11: =G5 -> 3 | C11: =IFERROR(B11/$A$5,0) -> 0.13043478 | E11: Venkata | F11: 7 | G11: 1 | I11: Other | J11: 4 | K11: 0 | L11: =IF(J11=0,0,K11/J11) -> 0
A12: Assigned | B12: {=SUMPRODUCT(('BSI PSURs'!A2:A45<>"")*('BSI PSURs'!A2:A45<>"TBD")*('BSI PSURs'!K2:K45="Assigned")*(1/COUNTIF('BSI PSURs'!A2:A45,'BSI PSURs'!A2:A45&"")))} -> 0 | C12: =IFERROR(B12/$A$5,0) -> 0 | E12: Terence | F12: 2 | G12: 0 | I12: TOTAL | J12: =SUM(J9:J11) -> 24 | K12: =SUM(K9:K11) -> 8 | L12: =K12/J12 -> 0.33333333
A13: Not Started | B13: =I5 -> 11 | C13: =IFERROR(B13/$A$5,0) -> 0.47826087 | E13: TOTAL | F13: =SUM(F9:F12) -> 21 | G13: =SUM(G9:G12) -> 8
A14: TBD | B14: {=SUMPRODUCT(('BSI PSURs'!A2:A45<>"")*('BSI PSURs'!A2:A45<>"TBD")*('BSI PSURs'!K2:K45="TBD")*(1/COUNTIF('BSI PSURs'!A2:A45,'BSI PSURs'!A2:A45&"")))} -> 1 | C14: =IFERROR(B14/$A$5,0) -> 0.043478261
A16: 🎯 DEVICE CLASS BREAKDOWN | E16: ⚡ PRIORITY BREAKDOWN | I16: ⏰ NEXT 30 DAYS - CRITICAL DEADLINES
A17: Class | B17: Count | C17: % of Total | E17: Priority | F17: Count | G17: % of Total | I17: Metric | J17: Count
A18: Class III | B18: =COUNTIF('BSI PSURs'!E:E,"III") -> 23 | C18: =IF($A$5>0,B18/$A$5,0) -> 1 | E18: 🔴 OVERDUE | F18: =I46 -> 0 | G18: =IFERROR(F18/$A$5,0) -> 0 | I18: Due in 7 days | J18: =COUNTIFS('BSI PSURs'!O:O,">0",'BSI PSURs'!O:O,"<=7") -> 2
A19: Class IIb | B19: =COUNTIF('BSI PSURs'!E:E,"IIb") -> 0 | C19: =IF($A$5>0,B19/$A$5,0) -> 0 | E19: 🟠 URGENT | F19: =I47 -> 6 | G19: =IFERROR(F19/$A$5,0) -> 0.26086957 | I19: Due in 14 days | J19: =COUNTIFS('BSI PSURs'!O:O,">0",'BSI PSURs'!O:O,"<=14") -> 3
A20: Class IIa | B20: =COUNTIF('BSI PSURs'!E:E,"IIa") -> 1 | C20: =IF($A$5>0,B20/$A$5,0) -> 0.043478261 | E20: 🟡 SOON | F20: =I48 -> 3 | G20: =IFERROR(F20/$A$5,0) -> 0.13043478 | I20: Due in 30 days | J20: =COUNTIFS('BSI PSURs'!O:O,">0",'BSI PSURs'!O:O,"<=30") -> 6
A21: Class I / Is | B21: =COUNTIFS('BSI PSURs'!E:E,"I")+COUNTIFS('BSI PSURs'!E:E,"Is") -> 0 | C21: =IF($A$5>0,B21/$A$5,0) -> 0 | E21: 🟢 ON TRACK | F21: =I49 -> 7 | G21: =IFERROR(F21/$A$5,0) -> 0.30434783 | I21: Currently Overdue | J21: =COUNTIF('BSI PSURs'!S:S,"⚠️ YES") -> 0
E22: ✅ DONE | F22: =I50 -> 7 | G22: =IFERROR(F22/$A$5,0) -> 0.30434783 | I22: Avg Days to Deadline | J22: =IFERROR(AVERAGEIF('BSI PSURs'!O:O,">0"),0) -> 62.625
E23: ⚪ TBD | F23: =I51 -> 0 | G23: =IFERROR(F23/$A$5,0) -> 0
A24: 📈 STATUS DISTRIBUTION | E24: 📊 WRITER WORKLOAD | I24: ⚡ PRIORITY DISTRIBUTION
A40: ⏱️ Dashboard auto-updates when you change Status, Due Date, or Writer on the 'BSI PSURs' sheet
A45: Status | B45: Count | D45: Writer | E45: Assigned | F45: Completed | H45: Priority | I45: Count
A46: Completed | B46: =B9 -> 7 | D46: Harish | E46: 9 | F46: 5 | H46: OVERDUE | I46: {=SUMPRODUCT(('BSI PSURs'!A2:A45<>"")*('BSI PSURs'!A2:A45<>"TBD")*(ISNUMBER(SEARCH("OVERDUE",'BSI PSURs'!P2:P45)))*(1/COUNTIF('BSI PSURs'!A2:A45,'BSI PSURs'!A2:A45&"")))} -> 0
A47: In Progress | B47: =B10 -> 1 | D47: Jeff | E47: 3 | F47: 2 | H47: URGENT | I47: {=SUMPRODUCT(('BSI PSURs'!A2:A45<>"")*('BSI PSURs'!A2:A45<>"TBD")*(ISNUMBER(SEARCH("URGENT",'BSI PSURs'!P2:P45)))*(1/COUNTIF('BSI PSURs'!A2:A45,'BSI PSURs'!A2:A45&"")))} -> 6
A48: In Review | B48: =B11 -> 3 | D48: Venkata | E48: 7 | F48: 1 | H48: SOON | I48: {=SUMPRODUCT(('BSI PSURs'!A2:A45<>"")*('BSI PSURs'!A2:A45<>"TBD")*(ISNUMBER(SEARCH("SOON",'BSI PSURs'!P2:P45)))*(1/COUNTIF('BSI PSURs'!A2:A45,'BSI PSURs'!A2:A45&"")))} -> 3
A49: Not Started | B49: =B13 -> 11 | D49: Terence | E49: 2 | F49: 0 | H49: ON TRACK | I49: {=SUMPRODUCT(('BSI PSURs'!A2:A45<>"")*('BSI PSURs'!A2:A45<>"TBD")*(ISNUMBER(SEARCH("ON TRACK",'BSI PSURs'!P2:P45)))*(1/COUNTIF('BSI PSURs'!A2:A45,'BSI PSURs'!A2:A45&"")))} -> 7
A50: TBD | B50: =B14 -> 1 | H50: DONE | I50: {=SUMPRODUCT(('BSI PSURs'!A2:A45<>"")*('BSI PSURs'!A2:A45<>"TBD")*(ISNUMBER(SEARCH("DONE",'BSI PSURs'!P2:P45)))*(1/COUNTIF('BSI PSURs'!A2:A45,'BSI PSURs'!A2:A45&"")))} -> 7
H51: TBD | I51: {=SUMPRODUCT(('BSI PSURs'!A2:A45<>"")*('BSI PSURs'!A2:A45<>"TBD")*('BSI PSURs'!P2:P45="⚪ TBD")*(1/COUNTIF('BSI PSURs'!A2:A45,'BSI PSURs'!A2:A45&"")))} -> 0

Sheet Writer Workload
A1: 👤 WRITER WORKLOAD TRACKER
A3: Writer | B3: Total Assigned | C3: Completed | D3: In Progress | E3: Not Started | F3: TBD | G3: Overdue | H3: Completion Rate | I3: Avg Days Left | J3: Earliest Due | K3: Risk Level
A4: Harish | B4: =COUNTIF('Maintenance PSURs'!L2:L52,"Harish") -> 3 | C4: =COUNTIFS('Maintenance PSURs'!L2:L52,"Harish",'Maintenance PSURs'!K2:K52,"Completed") -> 0 | D4: =COUNTIFS('Maintenance PSURs'!L2:L52,"Harish",'Maintenance PSURs'!K2:K52,"In progress") -> 1 | E4: =COUNTIFS('Maintenance PSURs'!L2:L52,"Harish",'Maintenance PSURs'!K2:K52,"Not Started") -> 1 | F4: =COUNTIFS('Maintenance PSURs'!L2:L52,"Harish",'Maintenance PSURs'!K2:K52,"TBD") -> 0 | G4: =COUNTIFS('Maintenance PSURs'!L2:L52,"Harish",'Maintenance PSURs'!S2:S52,"*YES*") -> 1 | H4: =IFERROR(C4/B4,0) -> 0 | I4: =IFERROR(ROUND(AVERAGEIFS('Maintenance PSURs'!O2:O52,'Maintenance PSURs'!L2:L52,"Harish",'Maintenance PSURs'!K2:K52,"<>Completed"),0),"N/A") -> 40 | J4: =IFERROR(_xlfn.MINIFS('Maintenance PSURs'!J2:J52,'Maintenance PSURs'!L2:L52,"Harish",'Maintenance PSURs'!K2:K52,"<>Completed",'Maintenance PSURs'!J2:J52,">0"),"N/A") -> 46112 | K4: =IF(G4>2,"🔴 HIGH",IF(G4>0,"🟠 MEDIUM","🟢 LOW")) -> 🟠 MEDIUM
A5: Jeff | B5: =COUNTIF('Maintenance PSURs'!L2:L52,"Jeff") -> 10 | C5: =COUNTIFS('Maintenance PSURs'!L2:L52,"Jeff",'Maintenance PSURs'!K2:K52,"Completed") -> 0 | D5: =COUNTIFS('Maintenance PSURs'!L2:L52,"Jeff",'Maintenance PSURs'!K2:K52,"In progress") -> 2 | E5: =COUNTIFS('Maintenance PSURs'!L2:L52,"Jeff",'Maintenance PSURs'!K2:K52,"Not Started") -> 7 | F5: =COUNTIFS('Maintenance PSURs'!L2:L52,"Jeff",'Maintenance PSURs'!K2:K52,"TBD") -> 0 | G5: =COUNTIFS('Maintenance PSURs'!L2:L52,"Jeff",'Maintenance PSURs'!S2:S52,"*YES*") -> 3 | H5: =IFERROR(C5/B5,0) -> 0 | I5: =IFERROR(ROUND(AVERAGEIFS('Maintenance PSURs'!O2:O52,'Maintenance PSURs'!L2:L52,"Jeff",'Maintenance PSURs'!K2:K52,"<>Completed"),0),"N/A") -> 21 | J5: =IFERROR(_xlfn.MINIFS('Maintenance PSURs'!J2:J52,'Maintenance PSURs'!L2:L52,"Jeff",'Maintenance PSURs'!K2:K52,"<>Completed",'Maintenance PSURs'!J2:J52,">0"),"N/A") -> 46080 | K5: =IF(G5>2,"🔴 HIGH",IF(G5>0,"🟠 MEDIUM","🟢 LOW")) -> 🔴 HIGH
A6: Venkata | B6: =COUNTIF('Maintenance PSURs'!L2:L52,"Venkata") -> 7 | C6: =COUNTIFS('Maintenance PSURs'!L2:L52,"Venkata",'Maintenance PSURs'!K2:K52,"Completed") -> 1 | D6: =COUNTIFS('Maintenance PSURs'!L2:L52,"Venkata",'Maintenance PSURs'!K2:K52,"In progress") -> 2 | E6: =COUNTIFS('Maintenance PSURs'!L2:L52,"Venkata",'Maintenance PSURs'!K2:K52,"Not Started") -> 4 | F6: =COUNTIFS('Maintenance PSURs'!L2:L52,"Venkata",'Maintenance PSURs'!K2:K52,"TBD") -> 0 | G6: =COUNTIFS('Maintenance PSURs'!L2:L52,"Venkata",'Maintenance PSURs'!S2:S52,"*YES*") -> 3 | H6: =IFERROR(C6/B6,0) -> 0.14285714 | I6: =IFERROR(ROUND(AVERAGEIFS('Maintenance PSURs'!O2:O52,'Maintenance PSURs'!L2:L52,"Venkata",'Maintenance PSURs'!K2:K52,"<>Completed"),0),"N/A") -> 0 | J6: =IFERROR(_xlfn.MINIFS('Maintenance PSURs'!J2:J52,'Maintenance PSURs'!L2:L52,"Venkata",'Maintenance PSURs'!K2:K52,"<>Completed",'Maintenance PSURs'!J2:J52,">0"),"N/A") -> 46073 | K6: =IF(G6>2,"🔴 HIGH",IF(G6>0,"🟠 MEDIUM","🟢 LOW")) -> 🔴 HIGH
A7: Terence | B7: =COUNTIF('Maintenance PSURs'!L2:L52,"Terence*") -> 12 | C7: =COUNTIFS('Maintenance PSURs'!L2:L52,"Terence*",'Maintenance PSURs'!K2:K52,"Completed") -> 2 | D7: =COUNTIFS('Maintenance PSURs'!L2:L52,"Terence*",'Maintenance PSURs'!K2:K52,"In progress") -> 5 | E7: =COUNTIFS('Maintenance PSURs'!L2:L52,"Terence*",'Maintenance PSURs'!K2:K52,"Not Started") -> 1 | F7: =COUNTIFS('Maintenance PSURs'!L2:L52,"Terence*",'Maintenance PSURs'!K2:K52,"TBD") -> 0 | G7: =COUNTIFS('Maintenance PSURs'!L2:L52,"Terence*",'Maintenance PSURs'!S2:S52,"*YES*") -> 4 | H7: =IFERROR(C7/B7,0) -> 0.16666667 | I7: =IFERROR(ROUND(AVERAGEIFS('Maintenance PSURs'!O2:O52,'Maintenance PSURs'!L2:L52,"Terence*",'Maintenance PSURs'!K2:K52,"<>Completed"),0),"N/A") -> -23 | J7: =IFERROR(_xlfn.MINIFS('Maintenance PSURs'!J2:J52,'Maintenance PSURs'!L2:L52,"Terence*",'Maintenance PSURs'!K2:K52,"<>Completed",'Maintenance PSURs'!J2:J52,">0"),"N/A") -> 46080 | K7: =IF(G7>2,"🔴 HIGH",IF(G7>0,"🟠 MEDIUM","🟢 LOW")) -> 🔴 HIGH
A8: TOTAL | B8: =SUM(B4:B7) -> 32 | C8: =SUM(C4:C7) -> 3 | D8: =SUM(D4:D7) -> 10 | E8: =SUM(E4:E7) -> 13 | F8: =SUM(F4:F7) -> 0 | G8: =SUM(G4:G7) -> 11 | H8: =IFERROR(C8/B8,0) -> 0.09375
A10: 📝 DETAILED ASSIGNMENTS BY WRITER (Live-linked to Master Schedule)
A11: Writer | B11: PSUR ID | C11: Product Name | D11: Class | E11: Due Date | F11: Days Left | G11: Status | H11: Priority | I11: Overdue? | J11: Combined PSUR | K11: Notes
A12: {=_xlfn._xlws.SORT(CHOOSE({1,2,3,4,5,6,7,8,9,10,11},'Maintenance PSURs'!L2:L52,'Maintenance PSURs'!C2:C52,'Maintenance PSURs'!D2:D52,'Maintenance PSURs'!E2:E52,'Maintenance PSURs'!J2:J52,'Maintenance PSURs'!O2:O52,'Maintenance PSURs'!K2:K52,'Maintenance PSURs'!P2:P52,'Maintenance PSURs'!S2:S52,'Maintenance PSURs'!M2:M52,'Maintenance PSURs'!N2:N52),1,1)} -> Harish | B12: PSUR039 | C12: Acidified Tyrodes Solution (1060) | D12: III | E12: 46112 | F12: -6 | G12: In progress | H12: 🟠 URGENT | I12: ⚠️ YES | J12: None | K12: none
A13: Harish | B13: PSUR016 | C13: PICSI® Sperm Selection Device | D13: III | E13: 46203 | F13: 85 | G13: Not Started | H13: 🟢 ON TRACK | I13: No | J13: None | K13: none
A14: Harish | B14: PMS005R | C14: RI Syringes | D14: I | E14: 2026-06-06 | F14: N/A | G14: Assigned | H14: ⚪ TBD | I14: No | J14: None | K14: none
A15: Jeff | B15: PSUR041 | C15: Liquid Paraffin - CHANGE CURRENT REV C TO B AND B TO A | D15: IIa | E15: 46157 | F15: 39 | G15: Not Started | H15: 🟡 SOON | I15: No | J15: Combine in PSUR041 | K15: PSUR041, PSUR205, PSUR301, PSUR302 and PSUR303 are combined in PSUR041
A16: Jeff | B16: PSUR044 | C16: VitriFit™ | D16: IIa | E16: 46150 | F16: 32 | G16: Not Started | H16: 🟡 SOON | I16: No | J16: None | K16: none
A17: Jeff | B17: PSUR050 | C17: RI Witness EHP | D17: IIa | E17: 46080 | F17: -38 | G17: In Review | H17: 🔴 OVERDUE | I17: ⚠️ YES | J17: None | K17: In draft, need to release 3-6-26 Awaiting Sales/complaint data, updating to new template
A18: Jeff | B18: PSUR071 | C18: Mobius Elastic Retractors | D18: IIa | E18: 46094 | F18: -24 | G18: In progress | H18: 🔴 OVERDUE | I18: ⚠️ YES | J18: None | K18: Sales data request issued 3-24-26
A19: Jeff | B19: PSUR058 | C19: Apple-Hunt Trocars | D19: IIa | E19: 46186 | F19: 68 | G19: Not Started | H19: 🟢 ON TRACK | I19: No | J19: None | K19: none
A20: Jeff | B20: PSUR087 | C20: LifeGlobal Dishes GPS® Dishware | D20: IIa | E20: 46199 | F20: 81 | G20: Not Started | H20: 🟢 ON TRACK | I20: No | J20: None | K20: none
A21: Jeff | B21: PSUR068 | C21: Wallace Aspiration Pump | D21: I | E21: 04/30/2026 - Immediate | F21: N/A | G21: Not Started | H21: ⚪ TBD | I21: No | J21: None | K21: No available documents released in MC
A22: Jeff | B22: PSUR083 | C22: LifeDop Dopplers and Probes | D22: IIa | E22: 46108 | F22: -10 | G22: In progress | H22: 🔴 OVERDUE | I22: ⚠️ YES | J22: None | K22: none
A23: Jeff | B23: PMS007R | C23: Adult-Neonatal_Care | D23: I | E23: 2026-01-03 | F23: N/A | G23: Not Started | H23: ⚪ TBD | I23: No | J23: None | K23: none
A24: Jeff | B24: PSUR059 | C24: Assisted Reproduction Catheters | D24: I | E24: 4/30/2026 - Immediate | F24: N/A | G24: Not Started | H24: ⚪ TBD | I24: No | J24: None | K24: No available documents released in MC
A25: TBD | B25: PSUR007 | C25: LoneStar Retractor Kit | D25: IIa | E25: 46073 | F25: -45 | G25: In progress | H25: 🔴 OVERDUE | I25: ⚠️ YES | J25: None | K25: 0
A26: TBD | B26: PMS007R | C26: Retractors | D26: Is | E26: 0 | F26: N/A | G26: Not Started | H26: ⚪ TBD | I26: No | J26: Combine with PSUR007 | K26: 0
A27: TBD | B27: PMS062R | C27: Endometrial_Suction_Curette | D27: I | E27: Immediate | F27: N/A | G27: Not Started | H27: ⚪ TBD | I27: No | J27: None | K27: No available documents released in MC
A28: TBD | B28: PMS123R | C28: K-Systems Flex Short-term Incubator Module | D28: I | E28: 0 | F28: N/A | G28: Not Started | H28: ⚪ TBD | I28: No | J28: None | K28: Terence will be conforming
A29: TBD | B29: PMS124R | C29: Embryo Biopsy Kit | D29: I | E29: 0 | F29: N/A | G29: Not Started | H29: ⚪ TBD | I29: No | J29: None | K29: Terence will be conforming
A30: TBD | B30: PMS125R | C30: Endometrial Biopsy Kit | D30: I | E30: 0 | F30: N/A | G30: Not Started | H30: ⚪ TBD | I30: No | J30: None | K30: Terence will be conforming
A31: TBD | B31: PSUR018 | C31: LEEP ELECTRODES | D31: IIb | E31: 46290 | F31: 172 | G31: Not Started | H31: 🟢 ON TRACK | I31: No | J31: None | K31: 0
A32: TBD | B32: PSUR047 | C32: SynVitro® Hyadase | D32: III | E32: 46233 | F32: 115 | G32: Not Started | H32: 🟢 ON TRACK | I32: No | J32: None | K32: none
A33: TBD | B33: PSUR048 | C33: Integra 3 Micromanipulator | D33: IIa | E33: 46233 | F33: 115 | G33: Not Started | H33: 🟢 ON TRACK | I33: No | J33: None | K33: 0
A34: TBD | B34: PSUR060 | C34: Carter-Thomason Port Closure Products | D34: IIa | E34: 46262 | F34: 144 | G34: Not Started | H34: 🟢 ON TRACK | I34: No | J34: None | K34: none
A35: TBD | B35: PSUR073 | C35: IVF PASTEUR PIPETTES | D35: IIa | E35: 46241 | F35: 123 | G35: Not Started | H35: 🟢 ON TRACK | I35: No | J35: None | K35: none
A36: TBD | B36: PSUR105 | C36: Stripper Tips | D36: IIB | E36: 46234 | F36: 116 | G36: Not Started | H36: 🟢 ON TRACK | I36: No | J36: None | K36: 0
A37: TBD | B37: PSUR130 | C37: TD130 Bakri Postpartum Balloon | D37: IIa | E37: 46228 | F37: 110 | G37: Not Started | H37: 🟢 ON TRACK | I37: No | J37: None | K37: 0
A38: TBD | B38: PSUR131 | C38: TD131_Cervical Ripening Balloon (CRB) Products | D38: IIa | E38: 46332 | F38: 214 | G38: Not Started | H38: 🟢 ON TRACK | I38: No | J38: None | K38: 0
A39: TBD | B39: PSUR147 | C39: Global Total and Global HP | D39: III | E39: 46233 | F39: 115 | G39: Not Started | H39: 🟢 ON TRACK | I39: No | J39: None | K39: 0
A40: TBD | B40: PSUR148 | C40: Global Total Fert | D40: III | E40: 46255 | F40: 137 | G40: Not Started | H40: 🟢 ON TRACK | I40: No | J40: None | K40: 0
A41: TBD | B41: PSUR149 | C41: Global Total™ with HEPES, 50mL, 100mL HTF w/ HEPES, 100 mL, 500 mL Washing mHTF with HEPES & Phenol Red, 100mL, 500mL | D41: III | E41: 46262 | F41: 144 | G41: Not Started | H41: 🟢 ON TRACK | I41: No | J41: None | K41: 0
A42: TBD | B42: PSUR150 | C42: LifeGlobal™ Protein Supplement, 20mL LifeGlobal™ Protein Supplement, 50mL LifeGlobal™ Protein Supplement, 6 x 5mL Quinn's Advantage™ SPS Serum Protein Substitute 100 ml Quinn's Advantage™ SPS Serum Protein Substitute Kit, 12 x 12mL | D42: III | E42: 46283 | F42: 165 | G42: Not Started | H42: 🟢 ON TRACK | I42: No | J42: None | K42: 0
...

Sheet Timeline
A1: 📅 PSUR TIMELINE — Q1 & Q2 2026 GANTT VIEW
A2: PSUR ID | B2: Writer | C2: Status | D2: Due Date | E2: Jan 1H | F2: Jan 2H | G2: Feb 1H | H2: Feb 2H | I2: Mar 1H | J2: Mar 2H | K2: Apr 1H | L2: Apr 2H | M2: May 1H | N2: May 2H | O2: Jun 1H | P2: Jun 2H | Q2: Jul+ | R2: Days Left
A3: ='Maintenance PSURs'!C2 -> PMS002R | B3: ='Maintenance PSURs'!L2 -> Terence | C3: ='Maintenance PSURs'!K2 -> In progress | D3: ='Maintenance PSURs'!J2 -> 46113 | E3: =IF(AND(ISNUMBER($D3),$D3>=DATE(2026,1,1),$D3<=DATE(2026,1,15)),"█","") | F3: =IF(AND(ISNUMBER($D3),$D3>=DATE(2026,1,16),$D3<=DATE(2026,1,31)),"█","") | G3: =IF(AND(ISNUMBER($D3),$D3>=DATE(2026,2,1),$D3<=DATE(2026,2,14)),"█","") | H3: =IF(AND(ISNUMBER($D3),$D3>=DATE(2026,2,15),$D3<=DATE(2026,2,28)),"█","") | I3: =IF(AND(ISNUMBER($D3),$D3>=DATE(2026,3,1),$D3<=DATE(2026,3,15)),"█","") | J3: =IF(AND(ISNUMBER($D3),$D3>=DATE(2026,3,16),$D3<=DATE(2026,3,31)),"█","") | K3: =IF(AND(ISNUMBER($D3),$D3>=DATE(2026,4,1),$D3<=DATE(2026,4,15)),"█","") -> █ | L3: =IF(AND(ISNUMBER($D3),$D3>=DATE(2026,4,16),$D3<=DATE(2026,4,30)),"█","") | M3: =IF(AND(ISNUMBER($D3),$D3>=DATE(2026,5,1),$D3<=DATE(2026,5,15)),"█","") | N3: =IF(AND(ISNUMBER($D3),$D3>=DATE(2026,5,16),$D3<=DATE(2026,5,31)),"█","") | O3: =IF(AND(ISNUMBER($D3),$D3>=DATE(2026,6,1),$D3<=DATE(2026,6,15)),"█","") | P3: =IF(AND(ISNUMBER($D3),$D3>=DATE(2026,6,16),$D3<=DATE(2026,6,30)),"█","") | Q3: =IF(AND(ISNUMBER($D3),$D3>DATE(2026,6,30)),"█","") | R3: ='Maintenance PSURs'!O2 -> -5
A4: ='Maintenance PSURs'!C3 -> PMS003R | B4: ='Maintenance PSURs'!L3 -> Terence | C4: ='Maintenance PSURs'!K3 -> In Review | D4: ='Maintenance PSURs'!J3 -> 2026-01-15 | E4: =IF(AND(ISNUMBER($D4),$D4>=DATE(2026,1,1),$D4<=DATE(2026,1,15)),"█","") | F4: =IF(AND(ISNUMBER($D4),$D4>=DATE(2026,1,16),$D4<=DATE(2026,1,31)),"█","") | G4: =IF(AND(ISNUMBER($D4),$D4>=DATE(2026,2,1),$D4<=DATE(2026,2,14)),"█","") | H4: =IF(AND(ISNUMBER($D4),$D4>=DATE(2026,2,15),$D4<=DATE(2026,2,28)),"█","") | I4: =IF(AND(ISNUMBER($D4),$D4>=DATE(2026,3,1),$D4<=DATE(2026,3,15)),"█","") | J4: =IF(AND(ISNUMBER($D4),$D4>=DATE(2026,3,16),$D4<=DATE(2026,3,31)),"█","") | K4: =IF(AND(ISNUMBER($D4),$D4>=DATE(2026,4,1),$D4<=DATE(2026,4,15)),"█","") | L4: =IF(AND(ISNUMBER($D4),$D4>=DATE(2026,4,16),$D4<=DATE(2026,4,30)),"█","") | M4: =IF(AND(ISNUMBER($D4),$D4>=DATE(2026,5,1),$D4<=DATE(2026,5,15)),"█","") | N4: =IF(AND(ISNUMBER($D4),$D4>=DATE(2026,5,16),$D4<=DATE(2026,5,31)),"█","") | O4: =IF(AND(ISNUMBER($D4),$D4>=DATE(2026,6,1),$D4<=DATE(2026,6,15)),"█","") | P4: =IF(AND(ISNUMBER($D4),$D4>=DATE(2026,6,16),$D4<=DATE(2026,6,30)),"█","") | Q4: =IF(AND(ISNUMBER($D4),$D4>DATE(2026,6,30)),"█","") | R4: ='Maintenance PSURs'!O3 -> N/A
A5: ='Maintenance PSURs'!C4 -> PSUR007 | B5: ='Maintenance PSURs'!L4 -> TBD | C5: ='Maintenance PSURs'!K4 -> In progress | D5: ='Maintenance PSURs'!J4 -> 46073 | E5: =IF(AND(ISNUMBER($D5),$D5>=DATE(2026,1,1),$D5<=DATE(2026,1,15)),"█","") | F5: =IF(AND(ISNUMBER($D5),$D5>=DATE(2026,1,16),$D5<=DATE(2026,1,31)),"█","") | G5: =IF(AND(ISNUMBER($D5),$D5>=DATE(2026,2,1),$D5<=DATE(2026,2,14)),"█","") | H5: =IF(AND(ISNUMBER($D5),$D5>=DATE(2026,2,15),$D5<=DATE(2026,2,28)),"█","") -> █ | I5: =IF(AND(ISNUMBER($D5),$D5>=DATE(2026,3,1),$D5<=DATE(2026,3,15)),"█","") | J5: =IF(AND(ISNUMBER($D5),$D5>=DATE(2026,3,16),$D5<=DATE(2026,3,31)),"█","") | K5: =IF(AND(ISNUMBER($D5),$D5>=DATE(2026,4,1),$D5<=DATE(2026,4,15)),"█","") | L5: =IF(AND(ISNUMBER($D5),$D5>=DATE(2026,4,16),$D5<=DATE(2026,4,30)),"█","") | M5: =IF(AND(ISNUMBER($D5),$D5>=DATE(2026,5,1),$D5<=DATE(2026,5,15)),"█","") | N5: =IF(AND(ISNUMBER($D5),$D5>=DATE(2026,5,16),$D5<=DATE(2026,5,31)),"█","") | O5: =IF(AND(ISNUMBER($D5),$D5>=DATE(2026,6,1),$D5<=DATE(2026,6,15)),"█","") | P5: =IF(AND(ISNUMBER($D5),$D5>=DATE(2026,6,16),$D5<=DATE(2026,6,30)),"█","") | Q5: =IF(AND(ISNUMBER($D5),$D5>DATE(2026,6,30)),"█","") | R5: ='Maintenance PSURs'!O4 -> -45
A6: ='Maintenance PSURs'!#REF! -> #REF! | B6: ='Maintenance PSURs'!#REF! -> #REF! | C6: ='Maintenance PSURs'!#REF! -> #REF! | D6: ='Maintenance PSURs'!#REF! -> #REF! | E6: =IF(AND(ISNUMBER($D6),$D6>=DATE(2026,1,1),$D6<=DATE(2026,1,15)),"█","") -> #REF! | F6: =IF(AND(ISNUMBER($D6),$D6>=DATE(2026,1,16),$D6<=DATE(2026,1,31)),"█","") -> #REF! | G6: =IF(AND(ISNUMBER($D6),$D6>=DATE(2026,2,1),$D6<=DATE(2026,2,14)),"█","") -> #REF! | H6: =IF(AND(ISNUMBER($D6),$D6>=DATE(2026,2,15),$D6<=DATE(2026,2,28)),"█","") -> #REF! | I6: =IF(AND(ISNUMBER($D6),$D6>=DATE(2026,3,1),$D6<=DATE(2026,3,15)),"█","") -> #REF! | J6: =IF(AND(ISNUMBER($D6),$D6>=DATE(2026,3,16),$D6<=DATE(2026,3,31)),"█","") -> #REF! | K6: =IF(AND(ISNUMBER($D6),$D6>=DATE(2026,4,1),$D6<=DATE(2026,4,15)),"█","") -> #REF! | L6: =IF(AND(ISNUMBER($D6),$D6>=DATE(2026,4,16),$D6<=DATE(2026,4,30)),"█","") -> #REF! | M6: =IF(AND(ISNUMBER($D6),$D6>=DATE(2026,5,1),$D6<=DATE(2026,5,15)),"█","") -> #REF! | N6: =IF(AND(ISNUMBER($D6),$D6>=DATE(2026,5,16),$D6<=DATE(2026,5,31)),"█","") -> #REF! | O6: =IF(AND(ISNUMBER($D6),$D6>=DATE(2026,6,1),$D6<=DATE(2026,6,15)),"█","") -> #REF! | P6: =IF(AND(ISNUMBER($D6),$D6>=DATE(2026,6,16),$D6<=DATE(2026,6,30)),"█","") -> #REF! | Q6: =IF(AND(ISNUMBER($D6),$D6>DATE(2026,6,30)),"█","") -> #REF! | R6: ='Maintenance PSURs'!#REF! -> #REF!
A7: ='Maintenance PSURs'!C5 -> PMS007R | B7: ='Maintenance PSURs'!L5 -> TBD | C7: ='Maintenance PSURs'!K5 -> Not Started | D7: ='Maintenance PSURs'!J5 -> 0 | E7: =IF(AND(ISNUMBER($D7),$D7>=DATE(2026,1,1),$D7<=DATE(2026,1,15)),"█","") | F7: =IF(AND(ISNUMBER($D7),$D7>=DATE(2026,1,16),$D7<=DATE(2026,1,31)),"█","") | G7: =IF(AND(ISNUMBER($D7),$D7>=DATE(2026,2,1),$D7<=DATE(2026,2,14)),"█","") | H7: =IF(AND(ISNUMBER($D7),$D7>=DATE(2026,2,15),$D7<=DATE(2026,2,28)),"█","") | I7: =IF(AND(ISNUMBER($D7),$D7>=DATE(2026,3,1),$D7<=DATE(2026,3,15)),"█","") | J7: =IF(AND(ISNUMBER($D7),$D7>=DATE(2026,3,16),$D7<=DATE(2026,3,31)),"█","") | K7: =IF(AND(ISNUMBER($D7),$D7>=DATE(2026,4,1),$D7<=DATE(2026,4,15)),"█","") | L7: =IF(AND(ISNUMBER($D7),$D7>=DATE(2026,4,16),$D7<=DATE(2026,4,30)),"█","") | M7: =IF(AND(ISNUMBER($D7),$D7>=DATE(2026,5,1),$D7<=DATE(2026,5,15)),"█","") | N7: =IF(AND(ISNUMBER($D7),$D7>=DATE(2026,5,16),$D7<=DATE(2026,5,31)),"█","") | O7: =IF(AND(ISNUMBER($D7),$D7>=DATE(2026,6,1),$D7<=DATE(2026,6,15)),"█","") | P7: =IF(AND(ISNUMBER($D7),$D7>=DATE(2026,6,16),$D7<=DATE(2026,6,30)),"█","") | Q7: =IF(AND(ISNUMBER($D7),$D7>DATE(2026,6,30)),"█","") | R7: ='Maintenance PSURs'!O5 -> N/A
A8: ='Maintenance PSURs'!C6 -> PMS008R | B8: ='Maintenance PSURs'!L6 -> Terence | C8: ='Maintenance PSURs'!K6 -> Completed | D8: ='Maintenance PSURs'!J6 -> 2026-03-01 | E8: =IF(AND(ISNUMBER($D8),$D8>=DATE(2026,1,1),$D8<=DATE(2026,1,15)),"█","") | F8: =IF(AND(ISNUMBER($D8),$D8>=DATE(2026,1,16),$D8<=DATE(2026,1,31)),"█","") | G8: =IF(AND(ISNUMBER($D8),$D8>=DATE(2026,2,1),$D8<=DATE(2026,2,14)),"█","") | H8: =IF(AND(ISNUMBER($D8),$D8>=DATE(2026,2,15),$D8<=DATE(2026,2,28)),"█","") | I8: =IF(AND(ISNUMBER($D8),$D8>=DATE(2026,3,1),$D8<=DATE(2026,3,15)),"█","") | J8: =IF(AND(ISNUMBER($D8),$D8>=DATE(2026,3,16),$D8<=DATE(2026,3,31)),"█","") | K8: =IF(AND(ISNUMBER($D8),$D8>=DATE(2026,4,1),$D8<=DATE(2026,4,15)),"█","") | L8: =IF(AND(ISNUMBER($D8),$D8>=DATE(2026,4,16),$D8<=DATE(2026,4,30)),"█","") | M8: =IF(AND(ISNUMBER($D8),$D8>=DATE(2026,5,1),$D8<=DATE(2026,5,15)),"█","") | N8: =IF(AND(ISNUMBER($D8),$D8>=DATE(2026,5,16),$D8<=DATE(2026,5,31)),"█","") | O8: =IF(AND(ISNUMBER($D8),$D8>=DATE(2026,6,1),$D8<=DATE(2026,6,15)),"█","") | P8: =IF(AND(ISNUMBER($D8),$D8>=DATE(2026,6,16),$D8<=DATE(2026,6,30)),"█","") | Q8: =IF(AND(ISNUMBER($D8),$D8>DATE(2026,6,30)),"█","") | R8: ='Maintenance PSURs'!O6 -> -
A9: ='Maintenance PSURs'!C7 -> PMS009R | B9: ='Maintenance PSURs'!L7 -> Terence | C9: ='Maintenance PSURs'!K7 -> In Review | D9: ='Maintenance PSURs'!J7 -> 0 | E9: =IF(AND(ISNUMBER($D9),$D9>=DATE(2026,1,1),$D9<=DATE(2026,1,15)),"█","") | F9: =IF(AND(ISNUMBER($D9),$D9>=DATE(2026,1,16),$D9<=DATE(2026,1,31)),"█","") | G9: =IF(AND(ISNUMBER($D9),$D9>=DATE(2026,2,1),$D9<=DATE(2026,2,14)),"█","") | H9: =IF(AND(ISNUMBER($D9),$D9>=DATE(2026,2,15),$D9<=DATE(2026,2,28)),"█","") | I9: =IF(AND(ISNUMBER($D9),$D9>=DATE(2026,3,1),$D9<=DATE(2026,3,15)),"█","") | J9: =IF(AND(ISNUMBER($D9),$D9>=DATE(2026,3,16),$D9<=DATE(2026,3,31)),"█","") | K9: =IF(AND(ISNUMBER($D9),$D9>=DATE(2026,4,1),$D9<=DATE(2026,4,15)),"█","") | L9: =IF(AND(ISNUMBER($D9),$D9>=DATE(2026,4,16),$D9<=DATE(2026,4,30)),"█","") | M9: =IF(AND(ISNUMBER($D9),$D9>=DATE(2026,5,1),$D9<=DATE(2026,5,15)),"█","") | N9: =IF(AND(ISNUMBER($D9),$D9>=DATE(2026,5,16),$D9<=DATE(2026,5,31)),"█","") | O9: =IF(AND(ISNUMBER($D9),$D9>=DATE(2026,6,1),$D9<=DATE(2026,6,15)),"█","") | P9: =IF(AND(ISNUMBER($D9),$D9>=DATE(2026,6,16),$D9<=DATE(2026,6,30)),"█","") | Q9: =IF(AND(ISNUMBER($D9),$D9>DATE(2026,6,30)),"█","") | R9: ='Maintenance PSURs'!O7 -> N/A
A10: ='Maintenance PSURs'!C8 -> PMS062R | B10: ='Maintenance PSURs'!L8 -> TBD | C10: ='Maintenance PSURs'!K8 -> Not Started | D10: ='Maintenance PSURs'!J8 -> Immediate | E10: =IF(AND(ISNUMBER($D10),$D10>=DATE(2026,1,1),$D10<=DATE(2026,1,15)),"█","") | F10: =IF(AND(ISNUMBER($D10),$D10>=DATE(2026,1,16),$D10<=DATE(2026,1,31)),"█","") | G10: =IF(AND(ISNUMBER($D10),$D10>=DATE(2026,2,1),$D10<=DATE(2026,2,14)),"█","") | H10: =IF(AND(ISNUMBER($D10),$D10>=DATE(2026,2,15),$D10<=DATE(2026,2,28)),"█","") | I10: =IF(AND(ISNUMBER($D10),$D10>=DATE(2026,3,1),$D10<=DATE(2026,3,15)),"█","") | J10: =IF(AND(ISNUMBER($D10),$D10>=DATE(2026,3,16),$D10<=DATE(2026,3,31)),"█","") | K10: =IF(AND(ISNUMBER($D10),$D10>=DATE(2026,4,1),$D10<=DATE(2026,4,15)),"█","") | L10: =IF(AND(ISNUMBER($D10),$D10>=DATE(2026,4,16),$D10<=DATE(2026,4,30)),"█","") | M10: =IF(AND(ISNUMBER($D10),$D10>=DATE(2026,5,1),$D10<=DATE(2026,5,15)),"█","") | N10: =IF(AND(ISNUMBER($D10),$D10>=DATE(2026,5,16),$D10<=DATE(2026,5,31)),"█","") | O10: =IF(AND(ISNUMBER($D10),$D10>=DATE(2026,6,1),$D10<=DATE(2026,6,15)),"█","") | P10: =IF(AND(ISNUMBER($D10),$D10>=DATE(2026,6,16),$D10<=DATE(2026,6,30)),"█","") | Q10: =IF(AND(ISNUMBER($D10),$D10>DATE(2026,6,30)),"█","") | R10: ='Maintenance PSURs'!O8 -> N/A
A11: ='Maintenance PSURs'!C9 -> PMS123R | B11: ='Maintenance PSURs'!L9 -> TBD | C11: ='Maintenance PSURs'!K9 -> Not Started | D11: ='Maintenance PSURs'!J9 -> 0 | E11: =IF(AND(ISNUMBER($D11),$D11>=DATE(2026,1,1),$D11<=DATE(2026,1,15)),"█","") | F11: =IF(AND(ISNUMBER($D11),$D11>=DATE(2026,1,16),$D11<=DATE(2026,1,31)),"█","") | G11: =IF(AND(ISNUMBER($D11),$D11>=DATE(2026,2,1),$D11<=DATE(2026,2,14)),"█","") | H11: =IF(AND(ISNUMBER($D11),$D11>=DATE(2026,2,15),$D11<=DATE(2026,2,28)),"█","") | I11: =IF(AND(ISNUMBER($D11),$D11>=DATE(2026,3,1),$D11<=DATE(2026,3,15)),"█","") | J11: =IF(AND(ISNUMBER($D11),$D11>=DATE(2026,3,16),$D11<=DATE(2026,3,31)),"█","") | K11: =IF(AND(ISNUMBER($D11),$D11>=DATE(2026,4,1),$D11<=DATE(2026,4,15)),"█","") | L11: =IF(AND(ISNUMBER($D11),$D11>=DATE(2026,4,16),$D11<=DATE(2026,4,30)),"█","") | M11: =IF(AND(ISNUMBER($D11),$D11>=DATE(2026,5,1),$D11<=DATE(2026,5,15)),"█","") | N11: =IF(AND(ISNUMBER($D11),$D11>=DATE(2026,5,16),$D11<=DATE(2026,5,31)),"█","") | O11: =IF(AND(ISNUMBER($D11),$D11>=DATE(2026,6,1),$D11<=DATE(2026,6,15)),"█","") | P11: =IF(AND(ISNUMBER($D11),$D11>=DATE(2026,6,16),$D11<=DATE(2026,6,30)),"█","") | Q11: =IF(AND(ISNUMBER($D11),$D11>DATE(2026,6,30)),"█","") | R11: ='Maintenance PSURs'!O9 -> N/A
A12: ='Maintenance PSURs'!C10 -> PMS124R | B12: ='Maintenance PSURs'!L10 -> TBD | C12: ='Maintenance PSURs'!K10 -> Not Started | D12: ='Maintenance PSURs'!J10 -> 0 | E12: =IF(AND(ISNUMBER($D12),$D12>=DATE(2026,1,1),$D12<=DATE(2026,1,15)),"█","") | F12: =IF(AND(ISNUMBER($D12),$D12>=DATE(2026,1,16),$D12<=DATE(2026,1,31)),"█","") | G12: =IF(AND(ISNUMBER($D12),$D12>=DATE(2026,2,1),$D12<=DATE(2026,2,14)),"█","") | H12: =IF(AND(ISNUMBER($D12),$D12>=DATE(2026,2,15),$D12<=DATE(2026,2,28)),"█","") | I12: =IF(AND(ISNUMBER($D12),$D12>=DATE(2026,3,1),$D12<=DATE(2026,3,15)),"█","") | J12: =IF(AND(ISNUMBER($D12),$D12>=DATE(2026,3,16),$D12<=DATE(2026,3,31)),"█","") | K12: =IF(AND(ISNUMBER($D12),$D12>=DATE(2026,4,1),$D12<=DATE(2026,4,15)),"█","") | L12: =IF(AND(ISNUMBER($D12),$D12>=DATE(2026,4,16),$D12<=DATE(2026,4,30)),"█","") | M12: =IF(AND(ISNUMBER($D12),$D12>=DATE(2026,5,1),$D12<=DATE(2026,5,15)),"█","") | N12: =IF(AND(ISNUMBER($D12),$D12>=DATE(2026,5,16),$D12<=DATE(2026,5,31)),"█","") | O12: =IF(AND(ISNUMBER($D12),$D12>=DATE(2026,6,1),$D12<=DATE(2026,6,15)),"█","") | P12: =IF(AND(ISNUMBER($D12),$D12>=DATE(2026,6,16),$D12<=DATE(2026,6,30)),"█","") | Q12: =IF(AND(ISNUMBER($D12),$D12>DATE(2026,6,30)),"█","") | R12: ='Maintenance PSURs'!O10 -> N/A
A13: ='Maintenance PSURs'!C11 -> PMS125R | B13: ='Maintenance PSURs'!L11 -> TBD | C13: ='Maintenance PSURs'!K11 -> Not Started | D13: ='Maintenance PSURs'!J11 -> 0 | E13: =IF(AND(ISNUMBER($D13),$D13>=DATE(2026,1,1),$D13<=DATE(2026,1,15)),"█","") | F13: =IF(AND(ISNUMBER($D13),$D13>=DATE(2026,1,16),$D13<=DATE(2026,1,31)),"█","") | G13: =IF(AND(ISNUMBER($D13),$D13>=DATE(2026,2,1),$D13<=DATE(2026,2,14)),"█","") | H13: =IF(AND(ISNUMBER($D13),$D13>=DATE(2026,2,15),$D13<=DATE(2026,2,28)),"█","") | I13: =IF(AND(ISNUMBER($D13),$D13>=DATE(2026,3,1),$D13<=DATE(2026,3,15)),"█","") | J13: =IF(AND(ISNUMBER($D13),$D13>=DATE(2026,3,16),$D13<=DATE(2026,3,31)),"█","") | K13: =IF(AND(ISNUMBER($D13),$D13>=DATE(2026,4,1),$D13<=DATE(2026,4,15)),"█","") | L13: =IF(AND(ISNUMBER($D13),$D13>=DATE(2026,4,16),$D13<=DATE(2026,4,30)),"█","") | M13: =IF(AND(ISNUMBER($D13),$D13>=DATE(2026,5,1),$D13<=DATE(2026,5,15)),"█","") | N13: =IF(AND(ISNUMBER($D13),$D13>=DATE(2026,5,16),$D13<=DATE(2026,5,31)),"█","") | O13: =IF(AND(ISNUMBER($D13),$D13>=DATE(2026,6,1),$D13<=DATE(2026,6,15)),"█","") | P13: =IF(AND(ISNUMBER($D13),$D13>=DATE(2026,6,16),$D13<=DATE(2026,6,30)),"█","") | Q13: =IF(AND(ISNUMBER($D13),$D13>DATE(2026,6,30)),"█","") | R13: ='Maintenance PSURs'!O11 -> N/A
A14: ='Maintenance PSURs'!C12 -> PMSR017 | B14: ='Maintenance PSURs'!L12 -> Terence | C14: ='Maintenance PSURs'!K12 -> In Review | D14: ='Maintenance PSURs'!J12 -> 2026-01-23 | E14: =IF(AND(ISNUMBER($D14),$D14>=DATE(2026,1,1),$D14<=DATE(2026,1,15)),"█","") | F14: =IF(AND(ISNUMBER($D14),$D14>=DATE(2026,1,16),$D14<=DATE(2026,1,31)),"█","") | G14: =IF(AND(ISNUMBER($D14),$D14>=DATE(2026,2,1),$D14<=DATE(2026,2,14)),"█","") | H14: =IF(AND(ISNUMBER($D14),$D14>=DATE(2026,2,15),$D14<=DATE(2026,2,28)),"█","") | I14: =IF(AND(ISNUMBER($D14),$D14>=DATE(2026,3,1),$D14<=DATE(2026,3,15)),"█","") | J14: =IF(AND(ISNUMBER($D14),$D14>=DATE(2026,3,16),$D14<=DATE(2026,3,31)),"█","") | K14: =IF(AND(ISNUMBER($D14),$D14>=DATE(2026,4,1),$D14<=DATE(2026,4,15)),"█","") | L14: =IF(AND(ISNUMBER($D14),$D14>=DATE(2026,4,16),$D14<=DATE(2026,4,30)),"█","") | M14: =IF(AND(ISNUMBER($D14),$D14>=DATE(2026,5,1),$D14<=DATE(2026,5,15)),"█","") | N14: =IF(AND(ISNUMBER($D14),$D14>=DATE(2026,5,16),$D14<=DATE(2026,5,31)),"█","") | O14: =IF(AND(ISNUMBER($D14),$D14>=DATE(2026,6,1),$D14<=DATE(2026,6,15)),"█","") | P14: =IF(AND(ISNUMBER($D14),$D14>=DATE(2026,6,16),$D14<=DATE(2026,6,30)),"█","") | Q14: =IF(AND(ISNUMBER($D14),$D14>DATE(2026,6,30)),"█","") | R14: ='Maintenance PSURs'!O12 -> N/A
A15: ='Maintenance PSURs'!#REF! -> #REF! | B15: ='Maintenance PSURs'!#REF! -> #REF! | C15: ='Maintenance PSURs'!#REF! -> #REF! | D15: ='Maintenance PSURs'!#REF! -> #REF! | E15: =IF(AND(ISNUMBER($D15),$D15>=DATE(2026,1,1),$D15<=DATE(2026,1,15)),"█","") -> #REF! | F15: =IF(AND(ISNUMBER($D15),$D15>=DATE(2026,1,16),$D15<=DATE(2026,1,31)),"█","") -> #REF! | G15: =IF(AND(ISNUMBER($D15),$D15>=DATE(2026,2,1),$D15<=DATE(2026,2,14)),"█","") -> #REF! | H15: =IF(AND(ISNUMBER($D15),$D15>=DATE(2026,2,15),$D15<=DATE(2026,2,28)),"█","") -> #REF! | I15: =IF(AND(ISNUMBER($D15),$D15>=DATE(2026,3,1),$D15<=DATE(2026,3,15)),"█","") -> #REF! | J15: =IF(AND(ISNUMBER($D15),$D15>=DATE(2026,3,16),$D15<=DATE(2026,3,31)),"█","") -> #REF! | K15: =IF(AND(ISNUMBER($D15),$D15>=DATE(2026,4,1),$D15<=DATE(2026,4,15)),"█","") -> #REF! | L15: =IF(AND(ISNUMBER($D15),$D15>=DATE(2026,4,16),$D15<=DATE(2026,4,30)),"█","") -> #REF! | M15: =IF(AND(ISNUMBER($D15),$D15>=DATE(2026,5,1),$D15<=DATE(2026,5,15)),"█","") -> #REF! | N15: =IF(AND(ISNUMBER($D15),$D15>=DATE(2026,5,16),$D15<=DATE(2026,5,31)),"█","") -> #REF! | O15: =IF(AND(ISNUMBER($D15),$D15>=DATE(2026,6,1),$D15<=DATE(2026,6,15)),"█","") -> #REF! | P15: =IF(AND(ISNUMBER($D15),$D15>=DATE(2026,6,16),$D15<=DATE(2026,6,30)),"█","") -> #REF! | Q15: =IF(AND(ISNUMBER($D15),$D15>DATE(2026,6,30)),"█","") -> #REF! | R15: ='Maintenance PSURs'!#REF! -> #REF!
A16: ='Maintenance PSURs'!#REF! -> #REF! | B16: ='Maintenance PSURs'!#REF! -> #REF! | C16: ='Maintenance PSURs'!#REF! -> #REF! | D16: ='Maintenance PSURs'!#REF! -> #REF! | E16: =IF(AND(ISNUMBER($D16),$D16>=DATE(2026,1,1),$D16<=DATE(2026,1,15)),"█","") -> #REF! | F16: =IF(AND(ISNUMBER($D16),$D16>=DATE(2026,1,16),$D16<=DATE(2026,1,31)),"█","") -> #REF! | G16: =IF(AND(ISNUMBER($D16),$D16>=DATE(2026,2,1),$D16<=DATE(2026,2,14)),"█","") -> #REF! | H16: =IF(AND(ISNUMBER($D16),$D16>=DATE(2026,2,15),$D16<=DATE(2026,2,28)),"█","") -> #REF! | I16: =IF(AND(ISNUMBER($D16),$D16>=DATE(2026,3,1),$D16<=DATE(2026,3,15)),"█","") -> #REF! | J16: =IF(AND(ISNUMBER($D16),$D16>=DATE(2026,3,16),$D16<=DATE(2026,3,31)),"█","") -> #REF! | K16: =IF(AND(ISNUMBER($D16),$D16>=DATE(2026,4,1),$D16<=DATE(2026,4,15)),"█","") -> #REF! | L16: =IF(AND(ISNUMBER($D16),$D16>=DATE(2026,4,16),$D16<=DATE(2026,4,30)),"█","") -> #REF! | M16: =IF(AND(ISNUMBER($D16),$D16>=DATE(2026,5,1),$D16<=DATE(2026,5,15)),"█","") -> #REF! | N16: =IF(AND(ISNUMBER($D16),$D16>=DATE(2026,5,16),$D16<=DATE(2026,5,31)),"█","") -> #REF! | O16: =IF(AND(ISNUMBER($D16),$D16>=DATE(2026,6,1),$D16<=DATE(2026,6,15)),"█","") -> #REF! | P16: =IF(AND(ISNUMBER($D16),$D16>=DATE(2026,6,16),$D16<=DATE(2026,6,30)),"█","") -> #REF! | Q16: =IF(AND(ISNUMBER($D16),$D16>DATE(2026,6,30)),"█","") -> #REF! | R16: ='Maintenance PSURs'!#REF! -> #REF!
A17: ='Maintenance PSURs'!#REF! -> #REF! | B17: ='Maintenance PSURs'!#REF! -> #REF! | C17: ='Maintenance PSURs'!#REF! -> #REF! | D17: ='Maintenance PSURs'!#REF! -> #REF! | E17: =IF(AND(ISNUMBER($D17),$D17>=DATE(2026,1,1),$D17<=DATE(2026,1,15)),"█","") -> #REF! | F17: =IF(AND(ISNUMBER($D17),$D17>=DATE(2026,1,16),$D17<=DATE(2026,1,31)),"█","") -> #REF! | G17: =IF(AND(ISNUMBER($D17),$D17>=DATE(2026,2,1),$D17<=DATE(2026,2,14)),"█","") -> #REF! | H17: =IF(AND(ISNUMBER($D17),$D17>=DATE(2026,2,15),$D17<=DATE(2026,2,28)),"█","") -> #REF! | I17: =IF(AND(ISNUMBER($D17),$D17>=DATE(2026,3,1),$D17<=DATE(2026,3,15)),"█","") -> #REF! | J17: =IF(AND(ISNUMBER($D17),$D17>=DATE(2026,3,16),$D17<=DATE(2026,3,31)),"█","") -> #REF! | K17: =IF(AND(ISNUMBER($D17),$D17>=DATE(2026,4,1),$D17<=DATE(2026,4,15)),"█","") -> #REF! | L17: =IF(AND(ISNUMBER($D17),$D17>=DATE(2026,4,16),$D17<=DATE(2026,4,30)),"█","") -> #REF! | M17: =IF(AND(ISNUMBER($D17),$D17>=DATE(2026,5,1),$D17<=DATE(2026,5,15)),"█","") -> #REF! | N17: =IF(AND(ISNUMBER($D17),$D17>=DATE(2026,5,16),$D17<=DATE(2026,5,31)),"█","") -> #REF! | O17: =IF(AND(ISNUMBER($D17),$D17>=DATE(2026,6,1),$D17<=DATE(2026,6,15)),"█","") -> #REF! | P17: =IF(AND(ISNUMBER($D17),$D17>=DATE(2026,6,16),$D17<=DATE(2026,6,30)),"█","") -> #REF! | Q17: =IF(AND(ISNUMBER($D17),$D17>DATE(2026,6,30)),"█","") -> #REF! | R17: ='Maintenance PSURs'!#REF! -> #REF!
